[2025-04-02T09:07:04.489+0000] {local_task_job_runner.py:123} INFO - ::group::Pre task execution logs
[2025-04-02T09:07:04.500+0000] {taskinstance.py:2614} INFO - Dependencies all met for dep_context=non-requeueable deps ti=<TaskInstance: ecommerce_price_comparison.run_etl manual__2025-04-02T09:02:02.887425+00:00 [queued]>
[2025-04-02T09:07:04.505+0000] {taskinstance.py:2614} INFO - Dependencies all met for dep_context=requeueable deps ti=<TaskInstance: ecommerce_price_comparison.run_etl manual__2025-04-02T09:02:02.887425+00:00 [queued]>
[2025-04-02T09:07:04.505+0000] {taskinstance.py:2867} INFO - Starting attempt 2 of 2
[2025-04-02T09:07:04.514+0000] {taskinstance.py:2890} INFO - Executing <Task(PythonOperator): run_etl> on 2025-04-02 09:02:02.887425+00:00
[2025-04-02T09:07:04.520+0000] {warnings.py:112} WARNING - /home/***/.local/lib/python3.12/site-packages/***/task/task_runner/standard_task_runner.py:70: DeprecationWarning: This process (pid=146) is multi-threaded, use of fork() may lead to deadlocks in the child.
  pid = os.fork()

[2025-04-02T09:07:04.521+0000] {standard_task_runner.py:72} INFO - Started process 147 to run task
[2025-04-02T09:07:04.521+0000] {standard_task_runner.py:104} INFO - Running: ['***', 'tasks', 'run', 'ecommerce_price_comparison', 'run_etl', 'manual__2025-04-02T09:02:02.887425+00:00', '--job-id', '45', '--raw', '--subdir', 'DAGS_FOLDER/e-commerce_etl.py', '--cfg-path', '/tmp/tmphkd3arw5']
[2025-04-02T09:07:04.521+0000] {standard_task_runner.py:105} INFO - Job 45: Subtask run_etl
[2025-04-02T09:07:04.554+0000] {task_command.py:467} INFO - Running <TaskInstance: ecommerce_price_comparison.run_etl manual__2025-04-02T09:02:02.887425+00:00 [running]> on host c37750c9ab96
[2025-04-02T09:07:04.607+0000] {taskinstance.py:3134} INFO - Exporting env vars: AIRFLOW_CTX_DAG_OWNER='***' AIRFLOW_CTX_DAG_ID='ecommerce_price_comparison' AIRFLOW_CTX_TASK_ID='run_etl' AIRFLOW_CTX_EXECUTION_DATE='2025-04-02T09:02:02.887425+00:00' AIRFLOW_CTX_TRY_NUMBER='2' AIRFLOW_CTX_DAG_RUN_ID='manual__2025-04-02T09:02:02.887425+00:00'
[2025-04-02T09:07:04.608+0000] {taskinstance.py:732} INFO - ::endgroup::
[2025-04-02T09:07:04.643+0000] {taskinstance.py:3313} ERROR - Task failed with exception
Traceback (most recent call last):
  File "/home/airflow/.local/lib/python3.12/site-packages/airflow/models/taskinstance.py", line 768, in _execute_task
    result = _execute_callable(context=context, **execute_callable_kwargs)
             ^^^^^^^^^^^^^^^^^^^^^^^^^^^^^^^^^^^^^^^^^^^^^^^^^^^^^^^^^^^^^
  File "/home/airflow/.local/lib/python3.12/site-packages/airflow/models/taskinstance.py", line 734, in _execute_callable
    return ExecutionCallableRunner(
           ^^^^^^^^^^^^^^^^^^^^^^^^
  File "/home/airflow/.local/lib/python3.12/site-packages/airflow/utils/operator_helpers.py", line 252, in run
    return self.func(*args, **kwargs)
           ^^^^^^^^^^^^^^^^^^^^^^^^^^
  File "/home/airflow/.local/lib/python3.12/site-packages/airflow/models/baseoperator.py", line 424, in wrapper
    return func(self, *args, **kwargs)
           ^^^^^^^^^^^^^^^^^^^^^^^^^^^
  File "/home/airflow/.local/lib/python3.12/site-packages/airflow/operators/python.py", line 238, in execute
    return_value = self.execute_callable()
                   ^^^^^^^^^^^^^^^^^^^^^^^
  File "/home/airflow/.local/lib/python3.12/site-packages/airflow/operators/python.py", line 256, in execute_callable
    return runner.run(*self.op_args, **self.op_kwargs)
           ^^^^^^^^^^^^^^^^^^^^^^^^^^^^^^^^^^^^^^^^^^^
  File "/home/airflow/.local/lib/python3.12/site-packages/airflow/utils/operator_helpers.py", line 252, in run
    return self.func(*args, **kwargs)
           ^^^^^^^^^^^^^^^^^^^^^^^^^^
  File "/opt/airflow/dags/e-commerce_etl.py", line 29, in run_scraper
    subprocess.run(["python3", "/opt/airflow/scraper/scraper.py", filepath], check=True)
  File "/usr/local/lib/python3.12/subprocess.py", line 573, in run
    raise CalledProcessError(retcode, process.args,
subprocess.CalledProcessError: Command '['python3', '/opt/airflow/scraper/scraper.py', '/opt/airflow/output/output_2025-04-02.xlsx']' returned non-zero exit status 2.
[2025-04-02T09:07:04.652+0000] {taskinstance.py:1226} INFO - Marking task as FAILED. dag_id=ecommerce_price_comparison, task_id=run_etl, run_id=manual__2025-04-02T09:02:02.887425+00:00, execution_date=20250402T090202, start_date=20250402T090704, end_date=20250402T090704
[2025-04-02T09:07:04.669+0000] {taskinstance.py:341} INFO - ::group::Post task execution logs
[2025-04-02T09:07:04.669+0000] {standard_task_runner.py:124} ERROR - Failed to execute job 45 for task run_etl (Command '['python3', '/opt/airflow/scraper/scraper.py', '/opt/airflow/output/output_2025-04-02.xlsx']' returned non-zero exit status 2.; 147)
Traceback (most recent call last):
  File "/home/airflow/.local/lib/python3.12/site-packages/airflow/task/task_runner/standard_task_runner.py", line 117, in _start_by_fork
    ret = args.func(args, dag=self.dag)
          ^^^^^^^^^^^^^^^^^^^^^^^^^^^^^
  File "/home/airflow/.local/lib/python3.12/site-packages/airflow/cli/cli_config.py", line 49, in command
    return func(*args, **kwargs)
           ^^^^^^^^^^^^^^^^^^^^^
  File "/home/airflow/.local/lib/python3.12/site-packages/airflow/utils/cli.py", line 116, in wrapper
    return f(*args, **kwargs)
           ^^^^^^^^^^^^^^^^^^
  File "/home/airflow/.local/lib/python3.12/site-packages/airflow/cli/commands/task_command.py", line 483, in task_run
    task_return_code = _run_task_by_selected_method(args, _dag, ti)
                       ^^^^^^^^^^^^^^^^^^^^^^^^^^^^^^^^^^^^^^^^^^^^
  File "/home/airflow/.local/lib/python3.12/site-packages/airflow/cli/commands/task_command.py", line 256, in _run_task_by_selected_method
    return _run_raw_task(args, ti)
           ^^^^^^^^^^^^^^^^^^^^^^^
  File "/home/airflow/.local/lib/python3.12/site-packages/airflow/cli/commands/task_command.py", line 341, in _run_raw_task
    return ti._run_raw_task(
           ^^^^^^^^^^^^^^^^^
  File "/home/airflow/.local/lib/python3.12/site-packages/airflow/utils/session.py", line 97, in wrapper
    return func(*args, session=session, **kwargs)
           ^^^^^^^^^^^^^^^^^^^^^^^^^^^^^^^^^^^^^^
  File "/home/airflow/.local/lib/python3.12/site-packages/airflow/models/taskinstance.py", line 3006, in _run_raw_task
    return _run_raw_task(
           ^^^^^^^^^^^^^^
  File "/home/airflow/.local/lib/python3.12/site-packages/airflow/models/taskinstance.py", line 274, in _run_raw_task
    TaskInstance._execute_task_with_callbacks(
  File "/home/airflow/.local/lib/python3.12/site-packages/airflow/models/taskinstance.py", line 3161, in _execute_task_with_callbacks
    result = self._execute_task(context, task_orig)
             ^^^^^^^^^^^^^^^^^^^^^^^^^^^^^^^^^^^^^^
  File "/home/airflow/.local/lib/python3.12/site-packages/airflow/models/taskinstance.py", line 3185, in _execute_task
    return _execute_task(self, context, task_orig)
           ^^^^^^^^^^^^^^^^^^^^^^^^^^^^^^^^^^^^^^^
  File "/home/airflow/.local/lib/python3.12/site-packages/airflow/models/taskinstance.py", line 768, in _execute_task
    result = _execute_callable(context=context, **execute_callable_kwargs)
             ^^^^^^^^^^^^^^^^^^^^^^^^^^^^^^^^^^^^^^^^^^^^^^^^^^^^^^^^^^^^^
  File "/home/airflow/.local/lib/python3.12/site-packages/airflow/models/taskinstance.py", line 734, in _execute_callable
    return ExecutionCallableRunner(
           ^^^^^^^^^^^^^^^^^^^^^^^^
  File "/home/airflow/.local/lib/python3.12/site-packages/airflow/utils/operator_helpers.py", line 252, in run
    return self.func(*args, **kwargs)
           ^^^^^^^^^^^^^^^^^^^^^^^^^^
  File "/home/airflow/.local/lib/python3.12/site-packages/airflow/models/baseoperator.py", line 424, in wrapper
    return func(self, *args, **kwargs)
           ^^^^^^^^^^^^^^^^^^^^^^^^^^^
  File "/home/airflow/.local/lib/python3.12/site-packages/airflow/operators/python.py", line 238, in execute
    return_value = self.execute_callable()
                   ^^^^^^^^^^^^^^^^^^^^^^^
  File "/home/airflow/.local/lib/python3.12/site-packages/airflow/operators/python.py", line 256, in execute_callable
    return runner.run(*self.op_args, **self.op_kwargs)
           ^^^^^^^^^^^^^^^^^^^^^^^^^^^^^^^^^^^^^^^^^^^
  File "/home/airflow/.local/lib/python3.12/site-packages/airflow/utils/operator_helpers.py", line 252, in run
    return self.func(*args, **kwargs)
           ^^^^^^^^^^^^^^^^^^^^^^^^^^
  File "/opt/airflow/dags/e-commerce_etl.py", line 29, in run_scraper
    subprocess.run(["python3", "/opt/airflow/scraper/scraper.py", filepath], check=True)
  File "/usr/local/lib/python3.12/subprocess.py", line 573, in run
    raise CalledProcessError(retcode, process.args,
subprocess.CalledProcessError: Command '['python3', '/opt/airflow/scraper/scraper.py', '/opt/airflow/output/output_2025-04-02.xlsx']' returned non-zero exit status 2.
[2025-04-02T09:07:04.695+0000] {local_task_job_runner.py:266} INFO - Task exited with return code 1
[2025-04-02T09:07:04.706+0000] {taskinstance.py:3901} INFO - 0 downstream tasks scheduled from follow-on schedule check
[2025-04-02T09:07:04.708+0000] {local_task_job_runner.py:245} INFO - ::endgroup::
